<?xml version="1.0" encoding="utf-8"?>
<!-- =================================================================================== -->
<!-- |    This document was autogenerated by xacro from autolabor_pro1.xacro           | -->
<!-- |    EDITING THIS FILE BY HAND IS NOT RECOMMENDED                                 | -->
<!-- =================================================================================== -->
<!-- Revolute-Revolute Manipulator -->
<robot name="autolabor_pro1">
  <gazebo reference="base_link">
    <mu1>0.3</mu1>
    <mu2>0.3</mu2>
  </gazebo>
  <gazebo reference="left_front_wheel">
    <mu1>0.5</mu1>
    <mu2>0.5</mu2>
  </gazebo>
  <gazebo reference="left_back_wheel">
    <mu1>0.5</mu1>
    <mu2>0.5</mu2>
  </gazebo>
  <gazebo reference="right_front_wheel">
    <mu1>0.5</mu1>
    <mu2>0.5</mu2>
  </gazebo>
  <gazebo reference="right_back_wheel">
    <mu1>0.5</mu1>
    <mu2>0.5</mu2>
  </gazebo>
  <gazebo>
    <plugin filename="libfour_wheel_diff_driver_plugin.so" name="autolabor_driver_gazebo_plugin">
      <commandTopic>cmd_vel</commandTopic>
      <odometryTopic>odom</odometryTopic>
      <odometryFrame>odom</odometryFrame>
      <robotBaseFrame>base_link</robotBaseFrame>
      <worldFrame>world</worldFrame>
      <publishWheelTF>false</publishWheelTF>
      <publishOdomTF>true</publishOdomTF>
      <publishWorldTF>true</publishWorldTF>
      <publishWheelJointState>false</publishWheelJointState>
      <legacyMode>false</legacyMode>
      <wheelSeparation>0.80</wheelSeparation>
      <wheelDiameter>0.25</wheelDiameter>
      <wheelAcceleration>0.0</wheelAcceleration>
      <wheelTorque>100.0</wheelTorque>
      <updateRate>10.0</updateRate>
      <leftFrontWheelJoint>joint_left_front</leftFrontWheelJoint>
      <leftBackWheelJoint>joint_left_back</leftBackWheelJoint>
      <rightFrontWheelJoint>joint_right_front</rightFrontWheelJoint>
      <rightBackWheelJoint>joint_right_back</rightBackWheelJoint>
    </plugin>
  </gazebo>
  <gazebo reference="imu_link">
    <gravity>true</gravity>
    <sensor name="imu_sensor" type="imu">
      <always_on>true</always_on>
      <update_rate>20</update_rate>
      <visualize>true</visualize>
      <topic>imu</topic>
      <plugin filename="libimu_plugin.so" name="imu_plugin">
        <topicName>imu</topicName>
        <bodyName>imu_link</bodyName>
        <updateRateHZ>10</updateRateHZ>
        <gaussianNoise>0.0</gaussianNoise>
        <xyzOffset>0 0 0</xyzOffset>
        <rpyOffset>0 0 0</rpyOffset>
        <frameName>imu_link</frameName>
        <enableOrientation>true</enableOrientation>
        <initialOrientationAsReference>false</initialOrientationAsReference>
      </plugin>
    </sensor>
  </gazebo>
  <gazebo reference="lider_1_link">
    <sensor name="sensor_ray" type="gpu_ray">
      <!--pose>0.4 0.0 0.3 0.0 0.0 0.0</pose-->
      <ray>
        <scan display="true">
          <horizontal>
            <samples>500</samples>
            <resolution>1.0</resolution>
            <min_angle>-1.0</min_angle>
            <max_angle>1.0</max_angle>
          </horizontal>
          <vertical>
            <samples>160</samples>
            <resolution>1.0</resolution>
            <min_angle>-0.1</min_angle>
            <max_angle>0.1</max_angle>
          </vertical>
        </scan>
        <range>
          <min>0.05</min>
          <max>160.0</max>
        </range>
      </ray>
      <plugin filename="libblocklaser_plugin.so" name="plugin_1">
        <gaussianNoise>0.00</gaussianNoise>
        <alwaysOn>true</alwaysOn>
        <updateRate>10</updateRate>
        <topicName>points2</topicName>
        <frameName>lider_1_link</frameName>
      </plugin>
      <always_on>true</always_on>
      <update_rate>10</update_rate>
    </sensor>
  </gazebo>
  <!-- Base Link -->
  <link name="base_link">
    <collision>
      <origin rpy="0 0 0" xyz="0 0 0.18288"/>
      <geometry>
        <box size="0.7248 0.4302 0.195"/>
      </geometry>
      <!--geometry>
        <mesh filename="package://autolabor_description/meshes/body_color.dae"/>
      </geometry-->
    </collision>
    <visual>
      <origin rpy="0 0 0" xyz="0 0 0"/>
      <geometry>
        <mesh filename="package://autolabor_description/meshes/pro1_body_color.dae"/>
      </geometry>
    </visual>
    <inertial>
      <origin rpy="0 0 0" xyz="0 0 0"/>
      <mass value="39"/>
      <inertia ixx="0.7245" ixy="0.0" ixz="0.0" iyy="1.80" iyz="0.0" izz="2.2857"/>
    </inertial>
  </link>
  <link name="left_front_wheel">
    <collision>
      <origin rpy="1.5708 0 0" xyz="0 0 0"/>
      <geometry>
        <cylinder length="0.0822" radius="0.127"/>
      </geometry>
      <!--geometry>
        <mesh filename="package://autolabor_description/meshes/wheel_color.dae"/>
      </geometry-->
    </collision>
    <visual>
      <origin rpy="0 0 0" xyz="0 0 0"/>
      <geometry>
        <mesh filename="package://autolabor_description/meshes/pro1_wheel_color.dae"/>
      </geometry>
    </visual>
    <inertial>
      <origin rpy="0 0 0" xyz="0 0 0"/>
      <mass value="1.5"/>
      <inertia ixx="0.013" ixy="0.0" ixz="0.0" iyy="0.0074" iyz="0.0" izz="0.0074"/>
    </inertial>
  </link>
  <link name="left_back_wheel">
    <collision>
      <origin rpy="1.5708 0 0" xyz="0 0 0"/>
      <geometry>
        <cylinder length="0.0822" radius="0.127"/>
      </geometry>
      <!--geometry>
        <mesh filename="package://autolabor_description/meshes/wheel_color.dae"/>
      </geometry-->
    </collision>
    <visual>
      <origin rpy="0 0 0" xyz="0 0 0"/>
      <geometry>
        <mesh filename="package://autolabor_description/meshes/pro1_wheel_color.dae"/>
      </geometry>
    </visual>
    <inertial>
      <origin rpy="0 0 0" xyz="0 0 0"/>
      <mass value="1.5"/>
      <inertia ixx="0.013" ixy="0.0" ixz="0.0" iyy="0.0074" iyz="0.0" izz="0.0074"/>
    </inertial>
  </link>
  <link name="right_front_wheel">
    <collision>
      <origin rpy="1.5708 0 0" xyz="0 0 0"/>
      <geometry>
        <cylinder length="0.0822" radius="0.127"/>
      </geometry>
      <!--geometry>
        <mesh filename="package://autolabor_description/meshes/wheel_color.dae"/>
      </geometry-->
    </collision>
    <visual>
      <origin rpy="0 0 3.14159265359" xyz="0 0 0"/>
      <geometry>
        <mesh filename="package://autolabor_description/meshes/pro1_wheel_color.dae"/>
      </geometry>
    </visual>
    <inertial>
      <origin rpy="0 0 3.14159265359" xyz="0 0 0"/>
      <mass value="1.5"/>
      <inertia ixx="0.013" ixy="0.0" ixz="0.0" iyy="0.0074" iyz="0.0" izz="0.0074"/>
    </inertial>
  </link>
  <link name="right_back_wheel">
    <collision>
      <origin rpy="1.5708 0 0" xyz="0 0 0"/>
      <geometry>
        <cylinder length="0.0822" radius="0.127"/>
      </geometry>
      <!--geometry>
        <mesh filename="package://autolabor_description/meshes/wheel_color.dae"/>
      </geometry-->
    </collision>
    <visual>
      <origin rpy="0 0 3.14159265359" xyz="0 0 0"/>
      <geometry>
        <mesh filename="package://autolabor_description/meshes/pro1_wheel_color.dae"/>
      </geometry>
    </visual>
    <inertial>
      <origin rpy="0 0 3.14159265359" xyz="0 0 0"/>
      <mass value="1.5"/>
      <inertia ixx="0.013" ixy="0.0" ixz="0.0" iyy="0.0074" iyz="0.0" izz="0.0074"/>
    </inertial>
  </link>
  <link name="imu_link">
    <collision>
      <origin rpy="0 0 0" xyz="0 0 0"/>
      <geometry>
        <box size="0.05 0.05 0.03"/>
      </geometry>
    </collision>
    <visual>
      <origin rpy="0 0 0" xyz="0 0 0"/>
      <geometry>
        <box size="0.05 0.05 0.03"/>
      </geometry>
    </visual>
    <inertial>
      <origin rpy="0 0 0" xyz="0 0 0"/>
      <mass value="0.1"/>
      <inertia ixx="0.013" ixy="0.0" ixz="0.0" iyy="0.0074" iyz="0.0" izz="0.0074"/>
    </inertial>
  </link>
  <link name="lider_1_link">
    <collision>
      <origin rpy="0 0 0" xyz="0 0 0"/>
      <geometry>
        <box size="0.03 0.03 0.03"/>
      </geometry>
    </collision>
    <visual>
      <origin rpy="0 0 0" xyz="0 0 0"/>
      <geometry>
        <box size="0.03 0.03 0.03"/>
      </geometry>
    </visual>
    <inertial>
      <origin rpy="0 0 0" xyz="0 0 0"/>
      <mass value="0.1"/>
      <inertia ixx="0.013" ixy="0.0" ixz="0.0" iyy="0.0074" iyz="0.0" izz="0.0074"/>
    </inertial>
  </link>
  <joint name="joint_left_front" type="continuous">
    <parent link="base_link"/>
    <child link="left_front_wheel"/>
    <origin rpy="0 0 0" xyz="0.19649 0.2643 0.11913"/>
    <axis xyz="0 1 0"/>
    <dynamics damping="0.7"/>
  </joint>
  <joint name="joint_left_back" type="continuous">
    <parent link="base_link"/>
    <child link="left_back_wheel"/>
    <origin rpy="0 0 0" xyz="-0.18988 0.2643 0.11913"/>
    <axis xyz="0 1 0"/>
    <dynamics damping="0.7"/>
  </joint>
  <joint name="joint_right_front" type="continuous">
    <parent link="base_link"/>
    <child link="right_front_wheel"/>
    <origin rpy="0 0 0" xyz="0.19649 -0.2643 0.11913"/>
    <axis xyz="0 1 0"/>
    <dynamics damping="0.7"/>
  </joint>
  <joint name="joint_right_back" type="continuous">
    <parent link="base_link"/>
    <child link="right_back_wheel"/>
    <origin rpy="0 0 0" xyz="-0.18988 -0.2643 0.11913"/>
    <axis xyz="0 1 0"/>
    <dynamics damping="0.7"/>
  </joint>
  <!--joint name="joint_imu" type="continuous"-->
  <joint name="joint_imu" type="fixed">
    <parent link="base_link"/>
    <child link="imu_link"/>
    <origin rpy="0 0 0" xyz="0 0 0.4"/>
  </joint>
  <joint name="joint_lidar_1" type="fixed">
    <parent link="base_link"/>
    <child link="lider_1_link"/>
    <origin rpy="0 0 0" xyz="0.4 0.0 0.3"/>
  </joint>
</robot>

